<?xml version="1.0" ?>
<!-- created with Phobos 1.0.1 "Capricious Choutengan" -->
<robot name="arduino_robot_arm">
    <link name="base">
        
<inertial>
            <origin xyz="0 0 0" rpy="0 0 0" />
            <mass value="0.01" />
            <inertia ixx="0.001" ixy="0" ixz="0" iyy="0.001" iyz="0" izz="0.001" />
        </inertial>

        <visual name="Base">
               <origin xyz="-0.26 0 0" rpy="0 0 0" />
            <geometry>
                <mesh filename="package://robot_arm_pkg/meshes/stl/1.stl" scale="0.00098 0.00098 0.00098" />
            </geometry>
        </visual>
        <collision name="Base">
            <origin xyz="-0.0029 0.00016 0.01165" rpy="3.14159 0 0" />
            <geometry>
                <cylinder radius="0.0592" length="0.05469" />
            </geometry>
        </collision>
    </link>
    <link name="waist">
        
<inertial>
            <origin xyz="0 0 0" rpy="0 0 0" />
            <mass value="0.001" />
            <inertia ixx="0.001" ixy="0" ixz="0" iyy="0.001" iyz="0" izz="0.001" />
        </inertial>

        <visual name="Waist">
                <origin xyz="-0.26 0 0" rpy="0 0 0" />
            <geometry>
                <mesh filename="package://robot_arm_pkg/meshes/stl/2.stl" scale="0.00098 0.00098 0.00098" />
            </geometry>
        </visual>
        <collision name="Waist.000">
                <origin xyz="0 0 0" rpy="0 0 0" />
            <geometry>
                <mesh filename="package://robot_arm_pkg/meshes/stl/2.stl" scale="0.00098 0.00098 0.00098" />
            </geometry>
        </collision>
    </link>
    <link name="arm1">
        
<inertial>
            <origin xyz="0 0 0" rpy="0 0 0" />
            <mass value="0.001" />
            <inertia ixx="0.001" ixy="0" ixz="0" iyy="0.001" iyz="0" izz="0.001" />
        </inertial>

        <visual name="Arm 01">
             <origin xyz="-0.15 0 -0.2" rpy="0 0 0" />
            <geometry>
                <mesh filename="package://robot_arm_pkg/meshes/stl/3.stl" scale="0.00098 0.00098 0.00098" />
            </geometry>
        </visual>
        <collision name="Arm 01">
               <origin xyz="0 0 0" rpy="0 0 0" />
            <geometry>
                <box size="0.04221 0.16277 0.02051" />
            </geometry>
        </collision>
    </link>
    <link name="arm2">
        
<inertial>
            <origin xyz="0 0 0" rpy="0 0 0" />
            <mass value="0.001" />
            <inertia ixx="0.001" ixy="0" ixz="0" iyy="0.001" iyz="0" izz="0.001" />
        </inertial>

        <visual name="Arm 02">
                <origin xyz="-0.55 0.05 -0.4" rpy="0 0 0" />
            <geometry>
                <mesh filename="package://robot_arm_pkg/meshes/stl/4.stl" scale="0.00098 0.00098 0.00098" />
            </geometry>
        </visual>
        <visual name="arm3">
               <origin xyz="-0.55 0.05 -0.4" rpy="0 0 0" />
            <geometry>
                <mesh filename="package://robot_arm_pkg/meshes/stl/5.stl" scale="0.00098 0.00098 0.00098" />
            </geometry>
        </visual>
        <collision name="Arm 02">
               <origin xyz="0 0 0" rpy="0 0 0" />
            <geometry>
                <box size="0.02681 0.16397 0.0384" />
            </geometry>
        </collision>
    </link>
    <link name="gripper">
        
<inertial>
            <origin xyz="0 0 0" rpy="0 0 0" />
            <mass value="0.001" />
            <inertia ixx="0.001" ixy="0" ixz="0" iyy="0.001" iyz="0" izz="0.001" />
        </inertial>

        <visual name="Gripper">
            <origin xyz="-0.015 0 -0.35" rpy="0 0 0" />
            <geometry>
                <mesh filename="package://robot_arm_pkg/meshes/stl/6.stl" scale="0.00098 0.00098 0.00098" />
            </geometry>
        </visual>
        <collision name="Gripper.000">
               <origin xyz="0 0 0" rpy="0 0 0" />
            <geometry>
                <mesh filename="package://robot_arm_pkg/meshes/stl/6.stl" scale="0.00098 0.00098 0.00098" />
            </geometry>
        </collision>
    </link>
    
    <joint name="base_joint" type="revolute">
         <origin xyz="0 0 0" rpy="0 0 0" />
        <parent link="base" />
        <child link="waist" />
        <axis xyz="0 0 1.0" />
        <limit lower="-1.571" upper="1.571" effort="1000.0" velocity="1.0" />
    </joint>
    <joint name="shoulder" type="revolute">
      <origin xyz="-0.07 0.07 0.2" rpy="0 0 -0.8" />
        <parent link="waist" />
        <child link="arm1" />
        <axis xyz="0 1.0 0" />
        <limit lower="-1.571" upper="0.36" effort="1000.0" velocity="1.0" />
    </joint>
    <joint name="elbow" type="revolute">
<origin xyz="0.42 -0.05 0.2" rpy="0 0 0.1" />
        <parent link="arm1" />
        <child link="arm2" />
        <axis xyz="0 1.0 0" />
        <limit lower="0" upper="1.57" effort="1000.0" velocity="1.0" />
    </joint>
    <joint name="wrist" type="revolute">
        <origin xyz="-0.55 0.05 -0.05" rpy="0 0 0" />
        <parent link="arm2" />
        <child link="gripper" />
        <axis xyz="0 1.0 0" />
        <limit lower="-1.57" upper="1.57" effort="1000.0" velocity="1.0" />
    </joint>
    
<transmission name="trans_base_joint">
        <type>transmission_interface/SimpleTransmission</type>
        <joint name="base_joint">
            <hardwareInterface>hardware_interface/PositionJointInterface</hardwareInterface>
        </joint>
        <actuator name="base_joint_motor">
            <hardwareInterface>hardware_interface/PositionJointInterface</hardwareInterface>
            <mechanicalReduction>1</mechanicalReduction>
        </actuator>
    </transmission>
    <transmission name="trans_shoulder">
        <type>transmission_interface/SimpleTransmission</type>
        <joint name="shoulder">
            <hardwareInterface>hardware_interface/PositionJointInterface</hardwareInterface>
        </joint>
        <actuator name="shoulder_motor">
            <hardwareInterface>hardware_interface/PositionJointInterface</hardwareInterface>
            <mechanicalReduction>1</mechanicalReduction>
        </actuator>
    </transmission>
    <transmission name="trans_elbow">
        <type>transmission_interface/SimpleTransmission</type>
        <joint name="elbow">
            <hardwareInterface>hardware_interface/PositionJointInterface</hardwareInterface>
        </joint>
        <actuator name="elbow_motor">
            <hardwareInterface>hardware_interface/PositionJointInterface</hardwareInterface>
            <mechanicalReduction>1</mechanicalReduction>
        </actuator>
    </transmission>
    <transmission name="trans_wrist">
        <type>transmission_interface/SimpleTransmission</type>
        <joint name="wrist">
            <hardwareInterface>hardware_interface/PositionJointInterface</hardwareInterface>
        </joint>
        <actuator name="wrist_motor">
            <hardwareInterface>hardware_interface/PositionJointInterface</hardwareInterface>
            <mechanicalReduction>1</mechanicalReduction>
        </actuator>
    </transmission>
    <gazebo>
        <plugin name="gazebo_ros_control" filename="libgazebo_ros_control.so">
            <robotNamespace>/</robotNamespace>
        </plugin>
    </gazebo>
</robot>
